Workbook

Sheet Pivot Analysis
A1: Salesperson Performance
A3: Salesperson | B3: Sum of Net Sales | C3: Sum of Quantity | D3: Count of Order Id
A4: Kiran | B4: 1671741 | C4: 76 | D4: 9
A5: priya | B5: 906435 | C5: 75 | D5: 10
A6: Rahul | B6: 638490 | C6: 60 | D6: 10
A7: Sneha | B7: 312985 | C7: 62 | D7: 10
A8: Amit | B8: 299331 | C8: 63 | D8: 10
A9: Grand Total | B9: 3828982 | C9: 336 | D9: 49
A12: Product Performance
A14: Product | B14: Sum of Net Sales | C14: Sum of Quantity | D14: Count of Order Id
A15: Laptop | B15: 2593250 | C15: 49 | D15: 9
A16: Monitor | B16: 411300 | C16: 24 | D16: 9
A17: Printer | B17: 302125 | C17: 25 | D17: 8
A18: Headset | B18: 225015 | C18: 66 | D18: 7
A19: keyboard | B19: 189100 | C19: 79 | D19: 9
A20: Mouse | B20: 108192 | C20: 93 | D20: 7
A21: Grand Total | B21: 3828982 | C21: 336 | D21: 49
A23: Region Performance
A25: Region | B25: Sum of Net Sales | C25: Sum of Quantity | D25: Count of Order Id
A26: East | B26: 1710885 | C26: 70 | D26: 12
A27: West | B27: 1190911 | C27: 104 | D27: 12
A28: North | B28: 476806 | C28: 99 | D28: 12
A29: South | B29: 450380 | C29: 63 | D29: 13
A30: Grand Total | B30: 3828982 | C30: 336 | D30: 49
A32: Order Status Analysis
A34: Order Status | B34: Count of Order Id
A35: Completed | B35: 34
A36: Cancelled | B36: 8
A37: Pending | B37: 7
A38: Grand Total | B38: 49
A40: Monthly Sales
A42: Month | B42: Sum of Net Sales | C42: Count of Order Id
A43: Sep | B43: 1301441 | C43: 30
A44: Oct | B44: 2527541 | C44: 19
A45: Grand Total | B45: 3828982 | C45: 49

Sheet Sales_Data
A1: Order Id | B1: Order Date | C1: Salesperson | D1: Region | E1: Product | F1: Category | G1: Quantity | H1: Unit Price | I1: Discount | J1: Discount %2 | K1: Payment Mode | L1: Order Status | M1: Sales Amount | N1: Discount Amount | O1: Net Sales
A2: ORD035 | B2: 46314 | C2: Kiran | D2: East | E2: Laptop | F2: Accessories | G2: 15 | H2: 55000 | I2: 2 | J2: =I2/100 -> 0.02 | K2: Cash | L2: Completed | M2: =SalesData[[#This Row],[Quantity]]*SalesData[[#This Row],[Unit Price]] -> 825000 | N2: =SalesData[[#This Row],[Sales Amount]]*SalesData[[#This Row],[Discount %2]] -> 16500 | O2: =SalesData[[#This Row],[Sales Amount]]-SalesData[[#This Row],[Discount Amount]] -> 808500
A3: ORD040 | B3: 46316 | C3: Kiran | D3: West | E3: Laptop | F3: Electronics | G3: 12 | H3: 55000 | I3: 4 | J3: =I3/100 -> 0.04 | K3: Cash | L3: Completed | M3: =SalesData[[#This Row],[Quantity]]*SalesData[[#This Row],[Unit Price]] -> 660000 | N3: =SalesData[[#This Row],[Sales Amount]]*SalesData[[#This Row],[Discount %2]] -> 26400 | O3: =SalesData[[#This Row],[Sales Amount]]-SalesData[[#This Row],[Discount Amount]] -> 633600
A4: ORD047 | B4: 46320 | C4: priya | D4: East | E4: laptop | F4: Accessories | G4: 11 | H4: 55000 | I4: 4 | J4: =I4/100 -> 0.04 | K4: UPI | L4: Pending | M4: =SalesData[[#This Row],[Quantity]]*SalesData[[#This Row],[Unit Price]] -> 605000 | N4: =SalesData[[#This Row],[Sales Amount]]*SalesData[[#This Row],[Discount %2]] -> 24200 | O4: =SalesData[[#This Row],[Sales Amount]]-SalesData[[#This Row],[Discount Amount]] -> 580800
A5: ORD016 | B5: 46274 | C5: Rahul | D5: West | E5: Laptop | F5: Electronics | G5: 3 | H5: 55000 | I5: 8 | J5: =I5/100 -> 0.08 | K5: Credit Card | L5: Completed | M5: =SalesData[[#This Row],[Quantity]]*SalesData[[#This Row],[Unit Price]] -> 165000 | N5: =SalesData[[#This Row],[Sales Amount]]*SalesData[[#This Row],[Discount %2]] -> 13200 | O5: =SalesData[[#This Row],[Sales Amount]]-SalesData[[#This Row],[Discount Amount]] -> 151800
A6: ORD001 | B6: 46266 | C6: Rahul | D6: South | E6: Laptop | F6: Electronics | G6: 2 | H6: 55000 | I6: 5 | J6: =I6/100 -> 0.05 | K6: UPI | L6: Completed | M6: =SalesData[[#This Row],[Quantity]]*SalesData[[#This Row],[Unit Price]] -> 110000 | N6: =SalesData[[#This Row],[Sales Amount]]*SalesData[[#This Row],[Discount %2]] -> 5500 | O6: =SalesData[[#This Row],[Sales Amount]]-SalesData[[#This Row],[Discount Amount]] -> 104500
A7: ORD022 | B7: 46277 | C7: priya | D7: North | E7: Laptop | F7: Accessories | G7: 2 | H7: 55000 | I7: 5 | J7: =I7/100 -> 0.05 | K7: Bank Transfer | L7: Completed | M7: =SalesData[[#This Row],[Quantity]]*SalesData[[#This Row],[Unit Price]] -> 110000 | N7: =SalesData[[#This Row],[Sales Amount]]*SalesData[[#This Row],[Discount %2]] -> 5500 | O7: =SalesData[[#This Row],[Sales Amount]]-SalesData[[#This Row],[Discount Amount]] -> 104500
A8: ORD011 | B8: 46271 | C8: Rahul | D8: East | E8: Laptop | F8: Electronics | G8: 2 | H8: 55000 | I8: 6 | J8: =I8/100 -> 0.06 | K8: Credit Card | L8: Cancelled | M8: =SalesData[[#This Row],[Quantity]]*SalesData[[#This Row],[Unit Price]] -> 110000 | N8: =SalesData[[#This Row],[Sales Amount]]*SalesData[[#This Row],[Discount %2]] -> 6600 | O8: =SalesData[[#This Row],[Sales Amount]]-SalesData[[#This Row],[Discount Amount]] -> 103400
A9: ORD036 | B9: 46314 | C9: Rahul | D9: West | E9: Headset | F9: Accessories | G9: 25 | H9: 3500 | I9: 0 | J9: =I9/100 -> 0 | K9: UPI | L9: Pending | M9: =SalesData[[#This Row],[Quantity]]*SalesData[[#This Row],[Unit Price]] -> 87500 | N9: =SalesData[[#This Row],[Sales Amount]]*SalesData[[#This Row],[Discount %2]] -> 0 | O9: =SalesData[[#This Row],[Sales Amount]]-SalesData[[#This Row],[Discount Amount]] -> 87500
A10: ORD025 | B10: 46278 | C10: Kiran | D10: South | E10: Monitor | F10: Accessories | G10: 4 | H10: 18000 | I10: 6 | J10: =I10/100 -> 0.06 | K10: UPI | L10: Cancelled | M10: =SalesData[[#This Row],[Quantity]]*SalesData[[#This Row],[Unit Price]] -> 72000 | N10: =SalesData[[#This Row],[Sales Amount]]*SalesData[[#This Row],[Discount %2]] -> 4320 | O10: =SalesData[[#This Row],[Sales Amount]]-SalesData[[#This Row],[Discount Amount]] -> 67680
A11: ORD008 | B11: 46270 | C11: Amit | D11: West | E11: Monitor | F11: Electronics | G11: 4 | H11: 18000 | I11: 7 | J11: =I11/100 -> 0.07 | K11: Credit Card | L11: Completed | M11: =SalesData[[#This Row],[Quantity]]*SalesData[[#This Row],[Unit Price]] -> 72000 | N11: =SalesData[[#This Row],[Sales Amount]]*SalesData[[#This Row],[Discount %2]] -> 5040 | O11: =SalesData[[#This Row],[Sales Amount]]-SalesData[[#This Row],[Discount Amount]] -> 66960
A12: ORD038 | B12: 46315 | C12: Amit | D12: North | E12: Printer | F12: Office Equipment | G12: 5 | H12: 12500 | I12: 6 | J12: =I12/100 -> 0.06 | K12: Bank Transfer | L12: Completed | M12: =SalesData[[#This Row],[Quantity]]*SalesData[[#This Row],[Unit Price]] -> 62500 | N12: =SalesData[[#This Row],[Sales Amount]]*SalesData[[#This Row],[Discount %2]] -> 3750 | O12: =SalesData[[#This Row],[Sales Amount]]-SalesData[[#This Row],[Discount Amount]] -> 58750
A13: ORD028 | B13: 46280 | C13: Amit | D13: West | E13: Laptop | F13: Accessories | G13: 1 | H13: 55000 | I13: 3 | J13: =I13/100 -> 0.03 | K13: Credit Card | L13: Pending | M13: =SalesData[[#This Row],[Quantity]]*SalesData[[#This Row],[Unit Price]] -> 55000 | N13: =SalesData[[#This Row],[Sales Amount]]*SalesData[[#This Row],[Discount %2]] -> 1650 | O13: =SalesData[[#This Row],[Sales Amount]]-SalesData[[#This Row],[Discount Amount]] -> 53350
... A50: ORD043 | B50: 46318 | C50: Amit | D50: East | E50: Mouse | F50: Office Equipment | G50: 4 | H50: 1200 | I50: 5 | J50: =I50/100 -> 0.05 | K50: Credit Card | L50: Pending | M50: =SalesData[[#This Row],[Quantity]]*SalesData[[#This Row],[Unit Price]] -> 4800 | N50: =SalesData[[#This Row],[Sales Amount]]*SalesData[[#This Row],[Discount %2]] -> 240 | O50: =SalesData[[#This Row],[Sales Amount]]-SalesData[[#This Row],[Discount Amount]] -> 4560

Sheet MIS_Report
A1: SALES MIS REPORT
A2: KPI | B2: Value
A3: Total Orders | B3: =COUNTA(SalesData[Order Id]) -> 49
A4: Total Quantity Sold | B4: =SUM(SalesData[Quantity]) -> 336
A5: Total Sales Amount | B5: =SUM(SalesData[Sales Amount]) -> 3979600
A6: Total Discount | B6: =SUM(SalesData[Discount Amount]) -> 154368
A7: Total Net Sales | B7: =SUM(SalesData[Net Sales]) -> 3825232
A8: Average Order Value | B8: =AVERAGE(SalesData[Net Sales]) -> 78065.959
A10: Salesperson Performance
A11: Salesperson | B11: Total Orders | C11: Total Net Sales
A12: Rahul | B12: =COUNTIF(SalesData[Salesperson],Sales_Data!C5) -> 10 | C12: =SUMIF(SalesData[Salesperson],Sales_Data!C5,SalesData[Net Sales]) -> 638490
A13: Priya | B13: =COUNTIF(SalesData[Salesperson],Sales_Data!C7) -> 10 | C13: =SUMIF(SalesData[Salesperson],Sales_Data!C7,SalesData[Net Sales]) -> 906435
A14: Amit | B14: =COUNTIF(SalesData[Salesperson],Sales_Data!C11) -> 10 | C14: =SUMIF(SalesData[Salesperson],Sales_Data!C11,SalesData[Net Sales]) -> 295581
A15: Sneha | B15: =COUNTIF(SalesData[Salesperson],Sales_Data!C16) -> 10 | C15: =SUMIF(SalesData[Salesperson],Sales_Data!C16,SalesData[Net Sales]) -> 312985
A16: Kiran | B16: =COUNTIF(SalesData[Salesperson],Sales_Data!C10) -> 9 | C16: =SUMIF(SalesData[Salesperson],Sales_Data!C10,SalesData[Net Sales]) -> 1671741
A20: Product Performance
A21: Product | B21: Quantity Sold | C21: Total Net sales
A22: Laptop | B22: =SUMIF(SalesData[Product],Sales_Data!E2,SalesData[Quantity]) -> 49 | C22: =SUMIF(SalesData[Product],Sales_Data!E2,SalesData[Net Sales]) -> 2593250
A23: Monitor | B23: =SUMIF(SalesData[Product],Sales_Data!E10,SalesData[Quantity]) -> 24 | C23: =SUMIF(SalesData[Product],Sales_Data!E10,SalesData[Net Sales]) -> 411300
A24: Keyboard | B24: =SUMIF(SalesData[Product],Sales_Data!E19,SalesData[Quantity]) -> 79 | C24: =SUMIF(SalesData[Product],Sales_Data!E19,SalesData[Net Sales]) -> 189100
A25: Mouse | B25: =SUMIF(SalesData[Product],Sales_Data!E35,SalesData[Quantity]) -> 93 | C25: =SUMIF(SalesData[Product],Sales_Data!E35,SalesData[Net Sales]) -> 108192
A26: Headset | B26: =SUMIF(SalesData[Product],Sales_Data!E9,SalesData[Quantity]) -> 66 | C26: =SUMIF(SalesData[Product],Sales_Data!E9,SalesData[Net Sales]) -> 225015
A28: Region Performance
A29: Region | B29: Total Orders | C29: Total Net Sales
A30: North | B30: =COUNTIF(SalesData[Region],Sales_Data!D7) -> 12 | C30: =SUMIF(SalesData[Region],Sales_Data!D7,SalesData[Net Sales]) -> 473056
A31: South | B31: =COUNTIF(SalesData[Region],Sales_Data!D6) -> 13 | C31: =SUMIF(SalesData[Region],Sales_Data!D6,SalesData[Net Sales]) -> 450380
A32: East | B32: =COUNTIF(SalesData[Region],Sales_Data!D2) -> 12 | C32: =SUMIF(SalesData[Region],Sales_Data!D2,SalesData[Net Sales]) -> 1710885
A33: West | B33: =COUNTIF(SalesData[Region],Sales_Data!D3) -> 12 | C33: =SUMIF(SalesData[Region],Sales_Data!D3,SalesData[Net Sales]) -> 1190911
A35: Order Status Analysis
A36: Order Status | B36: Number of Orders | C36: % of Total Orders
A37: Completed | B37: =COUNTIF(SalesData[Order Status],Sales_Data!L2) -> 34 | C37: =B37/$B$3 -> 0.69387755
A38: Pending | B38: =COUNTIF(SalesData[Order Status],Sales_Data!L4) -> 7 | C38: =B38/$B$3 -> 0.14285714
A39: Cancelled | B39: =COUNTIF(SalesData[Order Status],Sales_Data!L8) -> 8 | C39: =B39/$B$3 -> 0.16326531
A42: Management Insight | B42: Result
A43: Top Salesperson | B43: =INDEX(A12:A16,MATCH(MAX(C12:C16),C12:C16,0)) -> Kiran
A44: Lowest salesperson | B44: =INDEX(A12:A16,MATCH(MIN(C12:C16),C12:C16,0)) -> Amit
A45: Top Region | B45: =INDEX(A30:A33,MATCH(MAX(C30:C33),C30:C33,0)) -> East
A46: Lowest Region | B46: =INDEX(A30:A33,MATCH(MIN(C30:C33),C30:C33,0)) -> South
A47: Best Selling Product | B47: =INDEX(A22:A26,MATCH(MAX(B22:B26),B22:B26,0)) -> Mouse
A48: Highest Revenue Product | B48: =INDEX(A22:A26,MATCH(MAX(C22:C26),C22:C26,0)) -> Laptop
...

Sheet Dashboard
A1: Sales MIS Dashboard
